# Goxel 0.7.2
# One line per voxel
# X Y Z RRGGBB
2 1 0 696a6a
3 1 0 696a6a
4 1 0 696a6a
5 1 0 696a6a
14 1 0 696a6a
15 1 0 696a6a
2 2 0 696a6a
3 2 0 696a6a
4 2 0 696a6a
5 2 0 696a6a
14 2 0 696a6a
15 2 0 696a6a
2 3 0 696a6a
3 3 0 696a6a
4 3 0 696a6a
5 3 0 696a6a
14 3 0 696a6a
15 3 0 696a6a
2 4 0 696a6a
3 4 0 696a6a
4 4 0 696a6a
5 4 0 696a6a
14 4 0 696a6a
15 4 0 696a6a
2 13 0 696a6a
3 13 0 696a6a
4 13 0 696a6a
5 13 0 696a6a
14 13 0 696a6a
15 13 0 696a6a
2 14 0 696a6a
3 14 0 696a6a
4 14 0 696a6a
5 14 0 696a6a
14 14 0 696a6a
15 14 0 696a6a
2 15 0 696a6a
3 15 0 696a6a
4 15 0 696a6a
5 15 0 696a6a
14 15 0 696a6a
15 15 0 696a6a
2 1 1 847e87
3 1 1 847e87
4 1 1 847e87
5 1 1 847e87
14 1 1 847e87
15 1 1 847e87
2 2 1 847e87
3 2 1 847e87
4 2 1 847e87
5 2 1 847e87
14 2 1 847e87
15 2 1 847e87
2 3 1 847e87
3 3 1 847e87
4 3 1 847e87
5 3 1 847e87
14 3 1 847e87
15 3 1 847e87
2 4 1 847e87
3 4 1 847e87
4 4 1 847e87
5 4 1 847e87
14 4 1 847e87
15 4 1 847e87
2 13 1 847e87
3 13 1 847e87
4 13 1 847e87
5 13 1 847e87
14 13 1 847e87
15 13 1 847e87
2 14 1 847e87
3 14 1 847e87
4 14 1 847e87
5 14 1 847e87
14 14 1 847e87
15 14 1 847e87
2 15 1 847e87
3 15 1 847e87
4 15 1 847e87
5 15 1 847e87
14 15 1 847e87
15 15 1 847e87
2 1 2 847e87
3 1 2 847e87
4 1 2 847e87
5 1 2 847e87
6 1 2 9badb7
7 1 2 9badb7
8 1 2 9badb7
9 1 2 9badb7
10 1 2 9badb7
11 1 2 9badb7
12 1 2 9badb7
13 1 2 9badb7
14 1 2 847e87
15 1 2 847e87
2 2 2 847e87
3 2 2 847e87
4 2 2 847e87
5 2 2 847e87
6 2 2 9badb7
7 2 2 9badb7
8 2 2 9badb7
9 2 2 9badb7
10 2 2 9badb7
11 2 2 9badb7
12 2 2 9badb7
13 2 2 9badb7
14 2 2 847e87
15 2 2 847e87
2 3 2 847e87
3 3 2 847e87
4 3 2 847e87
5 3 2 847e87
6 3 2 9badb7
7 3 2 9badb7
8 3 2 9badb7
9 3 2 9badb7
10 3 2 9badb7
11 3 2 9badb7
12 3 2 9badb7
13 3 2 9badb7
14 3 2 847e87
15 3 2 847e87
2 4 2 847e87
3 4 2 847e87
4 4 2 847e87
5 4 2 847e87
6 4 2 9badb7
7 4 2 9badb7
8 4 2 9badb7
9 4 2 9badb7
10 4 2 9badb7
11 4 2 9badb7
12 4 2 9badb7
13 4 2 9badb7
14 4 2 847e87
15 4 2 847e87
2 5 2 9badb7
3 5 2 9badb7
4 5 2 9badb7
5 5 2 9badb7
6 5 2 9badb7
7 5 2 9badb7
8 5 2 9badb7
9 5 2 9badb7
10 5 2 9badb7
11 5 2 9badb7
12 5 2 9badb7
13 5 2 9badb7
14 5 2 9badb7
15 5 2 9badb7
2 6 2 9badb7
3 6 2 9badb7
4 6 2 9badb7
5 6 2 9badb7
6 6 2 9badb7
7 6 2 9badb7
8 6 2 9badb7
9 6 2 9badb7
10 6 2 9badb7
11 6 2 9badb7
12 6 2 9badb7
13 6 2 9badb7
14 6 2 9badb7
15 6 2 9badb7
2 7 2 9badb7
3 7 2 9badb7
4 7 2 9badb7
5 7 2 9badb7
6 7 2 9badb7
7 7 2 9badb7
8 7 2 9badb7
9 7 2 9badb7
10 7 2 9badb7
11 7 2 9badb7
12 7 2 9badb7
13 7 2 9badb7
14 7 2 9badb7
15 7 2 9badb7
2 8 2 9badb7
3 8 2 9badb7
4 8 2 9badb7
5 8 2 9badb7
6 8 2 9badb7
7 8 2 9badb7
8 8 2 9badb7
9 8 2 9badb7
10 8 2 9badb7
11 8 2 9badb7
12 8 2 9badb7
13 8 2 9badb7
14 8 2 9badb7
15 8 2 9badb7
2 9 2 9badb7
3 9 2 9badb7
4 9 2 9badb7
5 9 2 9badb7
6 9 2 9badb7
7 9 2 9badb7
8 9 2 9badb7
9 9 2 9badb7
10 9 2 9badb7
11 9 2 9badb7
12 9 2 9badb7
13 9 2 9badb7
14 9 2 9badb7
15 9 2 9badb7
2 10 2 9badb7
3 10 2 9badb7
4 10 2 9badb7
5 10 2 9badb7
6 10 2 9badb7
7 10 2 9badb7
8 10 2 9badb7
9 10 2 9badb7
10 10 2 9badb7
11 10 2 9badb7
12 10 2 9badb7
13 10 2 9badb7
14 10 2 9badb7
15 10 2 9badb7
2 11 2 9badb7
3 11 2 9badb7
4 11 2 9badb7
5 11 2 9badb7
6 11 2 9badb7
7 11 2 9badb7
8 11 2 9badb7
9 11 2 9badb7
10 11 2 9badb7
11 11 2 9badb7
12 11 2 9badb7
13 11 2 9badb7
14 11 2 9badb7
15 11 2 9badb7
2 12 2 9badb7
3 12 2 9badb7
4 12 2 9badb7
5 12 2 9badb7
6 12 2 9badb7
7 12 2 9badb7
8 12 2 9badb7
9 12 2 9badb7
10 12 2 9badb7
11 12 2 9badb7
12 12 2 9badb7
13 12 2 9badb7
14 12 2 9badb7
15 12 2 9badb7
2 13 2 847e87
3 13 2 847e87
4 13 2 847e87
5 13 2 847e87
6 13 2 9badb7
7 13 2 9badb7
8 13 2 9badb7
9 13 2 9badb7
10 13 2 9badb7
11 13 2 9badb7
12 13 2 9badb7
13 13 2 9badb7
14 13 2 847e87
15 13 2 847e87
2 14 2 847e87
3 14 2 847e87
4 14 2 847e87
5 14 2 847e87
6 14 2 9badb7
7 14 2 9badb7
8 14 2 9badb7
9 14 2 9badb7
10 14 2 9badb7
11 14 2 9badb7
12 14 2 9badb7
13 14 2 9badb7
14 14 2 847e87
15 14 2 847e87
2 15 2 847e87
3 15 2 847e87
4 15 2 847e87
5 15 2 847e87
6 15 2 9badb7
7 15 2 9badb7
8 15 2 9badb7
9 15 2 9badb7
10 15 2 9badb7
11 15 2 9badb7
12 15 2 9badb7
13 15 2 9badb7
14 15 2 847e87
15 15 2 847e87
2 1 3 847e87
3 1 3 847e87
4 1 3 847e87
5 1 3 847e87
6 1 3 9badb7
7 1 3 9badb7
8 1 3 9badb7
9 1 3 9badb7
10 1 3 9badb7
11 1 3 9badb7
12 1 3 9badb7
13 1 3 9badb7
14 1 3 847e87
15 1 3 847e87
2 2 3 847e87
3 2 3 847e87
4 2 3 847e87
5 2 3 847e87
6 2 3 847e87
7 2 3 847e87
8 2 3 847e87
9 2 3 847e87
10 2 3 847e87
11 2 3 847e87
12 2 3 847e87
13 2 3 847e87
14 2 3 847e87
15 2 3 847e87
2 3 3 847e87
3 3 3 847e87
4 3 3 847e87
5 3 3 847e87
6 3 3 847e87
7 3 3 847e87
8 3 3 847e87
9 3 3 847e87
10 3 3 847e87
11 3 3 847e87
12 3 3 847e87
13 3 3 847e87
14 3 3 847e87
15 3 3 847e87
2 4 3 847e87
3 4 3 847e87
4 4 3 847e87
5 4 3 847e87
6 4 3 847e87
7 4 3 847e87
8 4 3 847e87
9 4 3 847e87
10 4 3 847e87
11 4 3 847e87
12 4 3 847e87
13 4 3 847e87
14 4 3 847e87
15 4 3 847e87
2 5 3 847e87
3 5 3 847e87
4 5 3 847e87
5 5 3 847e87
6 5 3 847e87
7 5 3 847e87
8 5 3 847e87
9 5 3 847e87
10 5 3 847e87
11 5 3 847e87
12 5 3 847e87
13 5 3 847e87
14 5 3 847e87
15 5 3 847e87
2 6 3 847e87
3 6 3 847e87
4 6 3 847e87
5 6 3 847e87
6 6 3 847e87
7 6 3 847e87
8 6 3 847e87
9 6 3 847e87
10 6 3 847e87
11 6 3 847e87
12 6 3 847e87
13 6 3 847e87
14 6 3 847e87
15 6 3 847e87
2 7 3 847e87
3 7 3 847e87
4 7 3 847e87
5 7 3 847e87
6 7 3 847e87
7 7 3 847e87
8 7 3 847e87
9 7 3 847e87
10 7 3 847e87
11 7 3 847e87
12 7 3 847e87
13 7 3 847e87
14 7 3 847e87
15 7 3 847e87
2 8 3 847e87
3 8 3 847e87
4 8 3 847e87
5 8 3 847e87
6 8 3 847e87
7 8 3 847e87
8 8 3 847e87
9 8 3 847e87
10 8 3 847e87
11 8 3 847e87
12 8 3 847e87
13 8 3 847e87
14 8 3 847e87
15 8 3 847e87
2 9 3 847e87
3 9 3 847e87
4 9 3 847e87
5 9 3 847e87
6 9 3 847e87
7 9 3 847e87
8 9 3 847e87
9 9 3 847e87
10 9 3 847e87
11 9 3 847e87
12 9 3 847e87
13 9 3 847e87
14 9 3 847e87
15 9 3 847e87
2 10 3 847e87
3 10 3 847e87
4 10 3 847e87
5 10 3 847e87
6 10 3 847e87
7 10 3 847e87
8 10 3 847e87
9 10 3 847e87
10 10 3 847e87
11 10 3 847e87
12 10 3 847e87
13 10 3 847e87
14 10 3 847e87
15 10 3 847e87
2 11 3 847e87
3 11 3 847e87
4 11 3 847e87
5 11 3 847e87
6 11 3 847e87
7 11 3 847e87
8 11 3 847e87
9 11 3 847e87
10 11 3 847e87
11 11 3 847e87
12 11 3 847e87
13 11 3 847e87
14 11 3 847e87
15 11 3 847e87
2 12 3 847e87
3 12 3 847e87
4 12 3 847e87
5 12 3 847e87
6 12 3 847e87
7 12 3 847e87
8 12 3 847e87
9 12 3 847e87
10 12 3 847e87
11 12 3 847e87
12 12 3 847e87
13 12 3 847e87
14 12 3 847e87
15 12 3 847e87
2 13 3 847e87
3 13 3 847e87
4 13 3 847e87
5 13 3 847e87
6 13 3 847e87
7 13 3 847e87
8 13 3 847e87
9 13 3 847e87
10 13 3 847e87
11 13 3 847e87
12 13 3 847e87
13 13 3 847e87
14 13 3 847e87
15 13 3 847e87
2 14 3 847e87
3 14 3 847e87
4 14 3 847e87
5 14 3 847e87
6 14 3 847e87
7 14 3 847e87
8 14 3 847e87
9 14 3 847e87
10 14 3 847e87
11 14 3 847e87
12 14 3 847e87
13 14 3 847e87
14 14 3 847e87
15 14 3 847e87
2 15 3 847e87
3 15 3 847e87
4 15 3 847e87
5 15 3 847e87
6 15 3 847e87
7 15 3 847e87
8 15 3 847e87
9 15 3 847e87
10 15 3 847e87
11 15 3 847e87
12 15 3 847e87
13 15 3 847e87
14 15 3 847e87
15 15 3 847e87
2 1 4 847e87
3 1 4 847e87
4 1 4 847e87
5 1 4 847e87
6 1 4 847e87
7 1 4 847e87
8 1 4 847e87
9 1 4 847e87
10 1 4 847e87
11 1 4 847e87
12 1 4 847e87
13 1 4 847e87
14 1 4 847e87
15 1 4 847e87
2 2 4 847e87
3 2 4 847e87
4 2 4 847e87
5 2 4 847e87
6 2 4 847e87
7 2 4 847e87
8 2 4 847e87
9 2 4 847e87
10 2 4 847e87
11 2 4 847e87
12 2 4 847e87
13 2 4 847e87
14 2 4 847e87
15 2 4 847e87
2 3 4 847e87
3 3 4 847e87
4 3 4 847e87
5 3 4 847e87
6 3 4 847e87
7 3 4 847e87
8 3 4 847e87
9 3 4 847e87
10 3 4 847e87
11 3 4 847e87
12 3 4 847e87
13 3 4 847e87
14 3 4 847e87
15 3 4 847e87
2 4 4 847e87
3 4 4 847e87
4 4 4 847e87
5 4 4 847e87
6 4 4 847e87
7 4 4 847e87
8 4 4 847e87
9 4 4 847e87
10 4 4 847e87
11 4 4 847e87
12 4 4 847e87
13 4 4 847e87
14 4 4 847e87
15 4 4 847e87
2 5 4 847e87
3 5 4 847e87
4 5 4 847e87
5 5 4 847e87
6 5 4 847e87
7 5 4 847e87
8 5 4 847e87
9 5 4 847e87
10 5 4 847e87
11 5 4 847e87
12 5 4 847e87
13 5 4 847e87
14 5 4 847e87
15 5 4 847e87
2 6 4 847e87
3 6 4 847e87
4 6 4 847e87
5 6 4 847e87
6 6 4 847e87
7 6 4 847e87
8 6 4 847e87
9 6 4 847e87
10 6 4 847e87
11 6 4 847e87
12 6 4 847e87
13 6 4 847e87
14 6 4 847e87
15 6 4 847e87
2 7 4 847e87
3 7 4 847e87
4 7 4 847e87
5 7 4 847e87
6 7 4 847e87
7 7 4 847e87
8 7 4 847e87
9 7 4 847e87
10 7 4 847e87
11 7 4 847e87
12 7 4 847e87
13 7 4 847e87
14 7 4 847e87
15 7 4 847e87
2 8 4 847e87
3 8 4 847e87
4 8 4 847e87
5 8 4 847e87
6 8 4 847e87
7 8 4 847e87
8 8 4 847e87
9 8 4 847e87
10 8 4 847e87
11 8 4 847e87
12 8 4 847e87
13 8 4 847e87
14 8 4 847e87
15 8 4 847e87
2 9 4 847e87
3 9 4 847e87
4 9 4 847e87
5 9 4 847e87
6 9 4 847e87
7 9 4 847e87
8 9 4 847e87
9 9 4 847e87
10 9 4 847e87
11 9 4 847e87
12 9 4 847e87
13 9 4 847e87
14 9 4 847e87
15 9 4 847e87
2 10 4 847e87
3 10 4 847e87
4 10 4 847e87
5 10 4 847e87
6 10 4 847e87
7 10 4 847e87
8 10 4 847e87
9 10 4 847e87
10 10 4 847e87
11 10 4 847e87
12 10 4 847e87
13 10 4 847e87
14 10 4 847e87
15 10 4 847e87
2 11 4 847e87
3 11 4 847e87
4 11 4 847e87
5 11 4 847e87
6 11 4 847e87
7 11 4 847e87
8 11 4 847e87
9 11 4 847e87
10 11 4 847e87
11 11 4 847e87
12 11 4 847e87
13 11 4 847e87
14 11 4 847e87
15 11 4 847e87
2 12 4 847e87
3 12 4 847e87
4 12 4 847e87
5 12 4 847e87
6 12 4 847e87
7 12 4 847e87
8 12 4 847e87
9 12 4 847e87
10 12 4 847e87
11 12 4 847e87
12 12 4 847e87
13 12 4 847e87
14 12 4 847e87
15 12 4 847e87
2 13 4 847e87
3 13 4 847e87
4 13 4 847e87
5 13 4 847e87
6 13 4 847e87
7 13 4 847e87
8 13 4 847e87
9 13 4 847e87
10 13 4 847e87
11 13 4 847e87
12 13 4 847e87
13 13 4 847e87
14 13 4 847e87
15 13 4 847e87
2 14 4 847e87
3 14 4 847e87
4 14 4 847e87
5 14 4 847e87
6 14 4 847e87
7 14 4 847e87
8 14 4 847e87
9 14 4 847e87
10 14 4 847e87
11 14 4 847e87
12 14 4 847e87
13 14 4 847e87
14 14 4 847e87
15 14 4 847e87
2 15 4 847e87
3 15 4 847e87
4 15 4 847e87
5 15 4 847e87
6 15 4 847e87
7 15 4 847e87
8 15 4 847e87
9 15 4 847e87
10 15 4 847e87
11 15 4 847e87
12 15 4 847e87
13 15 4 847e87
14 15 4 847e87
15 15 4 847e87
2 1 5 847e87
3 1 5 847e87
4 1 5 847e87
5 1 5 847e87
6 1 5 847e87
7 1 5 847e87
8 1 5 847e87
9 1 5 847e87
10 1 5 847e87
11 1 5 847e87
12 1 5 847e87
13 1 5 847e87
14 1 5 847e87
15 1 5 847e87
2 2 5 847e87
3 2 5 847e87
4 2 5 847e87
5 2 5 847e87
6 2 5 847e87
7 2 5 847e87
8 2 5 847e87
9 2 5 847e87
10 2 5 847e87
11 2 5 847e87
12 2 5 847e87
13 2 5 847e87
14 2 5 847e87
15 2 5 847e87
2 3 5 847e87
3 3 5 847e87
4 3 5 847e87
5 3 5 847e87
6 3 5 847e87
7 3 5 847e87
8 3 5 847e87
9 3 5 847e87
10 3 5 847e87
11 3 5 847e87
12 3 5 847e87
13 3 5 847e87
14 3 5 847e87
15 3 5 847e87
2 4 5 847e87
3 4 5 847e87
4 4 5 847e87
5 4 5 847e87
6 4 5 847e87
7 4 5 847e87
8 4 5 847e87
9 4 5 847e87
10 4 5 847e87
11 4 5 847e87
12 4 5 847e87
13 4 5 847e87
14 4 5 847e87
15 4 5 847e87
2 5 5 847e87
3 5 5 847e87
4 5 5 847e87
5 5 5 847e87
6 5 5 847e87
7 5 5 847e87
8 5 5 847e87
9 5 5 847e87
10 5 5 847e87
11 5 5 847e87
12 5 5 847e87
13 5 5 847e87
14 5 5 847e87
15 5 5 847e87
2 6 5 847e87
3 6 5 847e87
4 6 5 847e87
5 6 5 847e87
6 6 5 847e87
7 6 5 847e87
8 6 5 847e87
9 6 5 847e87
10 6 5 847e87
11 6 5 847e87
12 6 5 847e87
13 6 5 847e87
14 6 5 847e87
15 6 5 847e87
2 7 5 847e87
3 7 5 847e87
4 7 5 847e87
5 7 5 847e87
6 7 5 847e87
7 7 5 847e87
8 7 5 847e87
9 7 5 847e87
10 7 5 847e87
11 7 5 847e87
12 7 5 847e87
13 7 5 847e87
14 7 5 847e87
15 7 5 847e87
2 8 5 847e87
3 8 5 847e87
4 8 5 847e87
5 8 5 847e87
6 8 5 847e87
7 8 5 847e87
8 8 5 847e87
9 8 5 847e87
10 8 5 847e87
11 8 5 847e87
12 8 5 847e87
13 8 5 847e87
14 8 5 847e87
15 8 5 847e87
2 9 5 847e87
3 9 5 847e87
4 9 5 847e87
5 9 5 847e87
6 9 5 847e87
7 9 5 847e87
8 9 5 847e87
9 9 5 847e87
10 9 5 847e87
11 9 5 847e87
12 9 5 847e87
13 9 5 847e87
14 9 5 847e87
15 9 5 847e87
2 10 5 847e87
3 10 5 847e87
4 10 5 847e87
5 10 5 847e87
6 10 5 847e87
7 10 5 847e87
8 10 5 847e87
9 10 5 847e87
10 10 5 847e87
11 10 5 847e87
12 10 5 847e87
13 10 5 847e87
14 10 5 847e87
15 10 5 847e87
2 11 5 847e87
3 11 5 847e87
4 11 5 847e87
5 11 5 847e87
6 11 5 847e87
7 11 5 847e87
8 11 5 847e87
9 11 5 847e87
10 11 5 847e87
11 11 5 847e87
12 11 5 847e87
13 11 5 847e87
14 11 5 847e87
15 11 5 847e87
2 12 5 847e87
3 12 5 847e87
4 12 5 847e87
5 12 5 847e87
6 12 5 847e87
7 12 5 847e87
8 12 5 847e87
9 12 5 847e87
10 12 5 847e87
11 12 5 847e87
12 12 5 847e87
13 12 5 847e87
14 12 5 847e87
15 12 5 847e87
2 13 5 847e87
3 13 5 847e87
4 13 5 847e87
5 13 5 847e87
6 13 5 847e87
7 13 5 847e87
8 13 5 847e87
9 13 5 847e87
10 13 5 847e87
11 13 5 847e87
12 13 5 847e87
13 13 5 847e87
14 13 5 847e87
15 13 5 847e87
2 14 5 847e87
3 14 5 847e87
4 14 5 847e87
5 14 5 847e87
6 14 5 847e87
7 14 5 847e87
8 14 5 847e87
9 14 5 847e87
10 14 5 847e87
11 14 5 847e87
12 14 5 847e87
13 14 5 847e87
14 14 5 847e87
15 14 5 847e87
2 15 5 847e87
3 15 5 847e87
4 15 5 847e87
5 15 5 847e87
6 15 5 847e87
7 15 5 847e87
8 15 5 847e87
9 15 5 847e87
10 15 5 847e87
11 15 5 847e87
12 15 5 847e87
13 15 5 847e87
14 15 5 847e87
15 15 5 847e87
6 0 6 ffffff
7 0 6 ffffff
8 0 6 ffffff
11 0 6 ffffff
12 0 6 ffffff
13 0 6 ffffff
0 1 6 696a6a
1 1 6 696a6a
2 1 6 847e87
3 1 6 847e87
4 1 6 847e87
5 1 6 847e87
6 1 6 847e87
7 1 6 847e87
8 1 6 847e87
9 1 6 847e87
10 1 6 847e87
11 1 6 847e87
12 1 6 847e87
13 1 6 847e87
14 1 6 847e87
15 1 6 847e87
2 2 6 847e87
3 2 6 847e87
4 2 6 847e87
5 2 6 847e87
6 2 6 847e87
7 2 6 847e87
8 2 6 847e87
9 2 6 847e87
10 2 6 847e87
11 2 6 847e87
12 2 6 847e87
13 2 6 847e87
14 2 6 847e87
15 2 6 847e87
2 3 6 847e87
3 3 6 847e87
4 3 6 847e87
5 3 6 847e87
6 3 6 847e87
7 3 6 847e87
8 3 6 847e87
9 3 6 847e87
10 3 6 847e87
11 3 6 847e87
12 3 6 847e87
13 3 6 847e87
14 3 6 847e87
15 3 6 847e87
2 4 6 847e87
3 4 6 847e87
4 4 6 847e87
5 4 6 847e87
6 4 6 847e87
7 4 6 847e87
8 4 6 847e87
9 4 6 847e87
10 4 6 847e87
11 4 6 847e87
12 4 6 847e87
13 4 6 847e87
14 4 6 847e87
15 4 6 847e87
2 5 6 847e87
3 5 6 847e87
4 5 6 847e87
5 5 6 847e87
6 5 6 847e87
7 5 6 847e87
8 5 6 847e87
9 5 6 847e87
10 5 6 847e87
11 5 6 847e87
12 5 6 847e87
13 5 6 847e87
14 5 6 847e87
15 5 6 847e87
2 6 6 847e87
3 6 6 847e87
4 6 6 847e87
5 6 6 847e87
6 6 6 847e87
7 6 6 847e87
8 6 6 847e87
9 6 6 847e87
10 6 6 847e87
11 6 6 847e87
12 6 6 847e87
13 6 6 847e87
14 6 6 847e87
15 6 6 847e87
2 7 6 847e87
3 7 6 847e87
4 7 6 847e87
5 7 6 847e87
6 7 6 847e87
7 7 6 847e87
8 7 6 847e87
9 7 6 847e87
10 7 6 847e87
11 7 6 847e87
12 7 6 847e87
13 7 6 847e87
14 7 6 847e87
15 7 6 847e87
2 8 6 847e87
3 8 6 847e87
4 8 6 847e87
5 8 6 847e87
6 8 6 847e87
7 8 6 847e87
8 8 6 847e87
9 8 6 847e87
10 8 6 847e87
11 8 6 847e87
12 8 6 847e87
13 8 6 847e87
14 8 6 847e87
15 8 6 847e87
2 9 6 847e87
3 9 6 847e87
4 9 6 847e87
5 9 6 847e87
6 9 6 847e87
7 9 6 847e87
8 9 6 847e87
9 9 6 847e87
10 9 6 847e87
11 9 6 847e87
12 9 6 847e87
13 9 6 847e87
14 9 6 847e87
15 9 6 847e87
2 10 6 847e87
3 10 6 847e87
4 10 6 847e87
5 10 6 847e87
6 10 6 847e87
7 10 6 847e87
8 10 6 847e87
9 10 6 847e87
10 10 6 847e87
11 10 6 847e87
12 10 6 847e87
13 10 6 847e87
14 10 6 847e87
15 10 6 847e87
2 11 6 847e87
3 11 6 847e87
4 11 6 847e87
5 11 6 847e87
6 11 6 847e87
7 11 6 847e87
8 11 6 847e87
9 11 6 847e87
10 11 6 847e87
11 11 6 847e87
12 11 6 847e87
13 11 6 847e87
14 11 6 847e87
15 11 6 847e87
2 12 6 847e87
3 12 6 847e87
4 12 6 847e87
5 12 6 847e87
6 12 6 847e87
7 12 6 847e87
8 12 6 847e87
9 12 6 847e87
10 12 6 847e87
11 12 6 847e87
12 12 6 847e87
13 12 6 847e87
14 12 6 847e87
15 12 6 847e87
2 13 6 847e87
3 13 6 847e87
4 13 6 847e87
5 13 6 847e87
6 13 6 847e87
7 13 6 847e87
8 13 6 847e87
9 13 6 847e87
10 13 6 847e87
11 13 6 847e87
12 13 6 847e87
13 13 6 847e87
14 13 6 847e87
15 13 6 847e87
2 14 6 847e87
3 14 6 847e87
4 14 6 847e87
5 14 6 847e87
6 14 6 847e87
7 14 6 847e87
8 14 6 847e87
9 14 6 847e87
10 14 6 847e87
11 14 6 847e87
12 14 6 847e87
13 14 6 847e87
14 14 6 847e87
15 14 6 847e87
2 15 6 847e87
3 15 6 847e87
4 15 6 847e87
5 15 6 847e87
6 15 6 847e87
7 15 6 847e87
8 15 6 847e87
9 15 6 847e87
10 15 6 847e87
11 15 6 847e87
12 15 6 847e87
13 15 6 847e87
14 15 6 847e87
15 15 6 847e87
6 0 7 ffffff
7 0 7 ffffff
8 0 7 ffffff
9 0 7 ffffff
10 0 7 ffffff
11 0 7 ffffff
12 0 7 ffffff
13 0 7 ffffff
2 1 7 847e87
3 1 7 847e87
4 1 7 847e87
5 1 7 847e87
6 1 7 847e87
7 1 7 847e87
8 1 7 847e87
9 1 7 847e87
10 1 7 847e87
11 1 7 847e87
12 1 7 847e87
13 1 7 847e87
14 1 7 847e87
15 1 7 847e87
2 2 7 847e87
3 2 7 847e87
4 2 7 847e87
5 2 7 847e87
6 2 7 847e87
7 2 7 847e87
8 2 7 847e87
9 2 7 847e87
10 2 7 847e87
11 2 7 847e87
12 2 7 847e87
13 2 7 847e87
14 2 7 847e87
15 2 7 847e87
2 3 7 847e87
3 3 7 847e87
4 3 7 847e87
5 3 7 847e87
6 3 7 847e87
7 3 7 847e87
8 3 7 847e87
9 3 7 847e87
10 3 7 847e87
11 3 7 847e87
12 3 7 847e87
13 3 7 847e87
14 3 7 847e87
15 3 7 847e87
2 4 7 847e87
3 4 7 847e87
4 4 7 847e87
5 4 7 847e87
6 4 7 847e87
7 4 7 847e87
8 4 7 847e87
9 4 7 847e87
10 4 7 847e87
11 4 7 847e87
12 4 7 847e87
13 4 7 847e87
14 4 7 847e87
15 4 7 847e87
2 5 7 847e87
3 5 7 847e87
4 5 7 847e87
5 5 7 847e87
6 5 7 847e87
7 5 7 847e87
8 5 7 847e87
9 5 7 847e87
10 5 7 847e87
11 5 7 847e87
12 5 7 847e87
13 5 7 847e87
14 5 7 847e87
15 5 7 847e87
2 6 7 847e87
3 6 7 847e87
4 6 7 847e87
5 6 7 847e87
6 6 7 847e87
7 6 7 847e87
8 6 7 847e87
9 6 7 847e87
10 6 7 847e87
11 6 7 847e87
12 6 7 847e87
13 6 7 847e87
14 6 7 847e87
15 6 7 847e87
2 7 7 847e87
3 7 7 847e87
4 7 7 847e87
5 7 7 847e87
6 7 7 847e87
7 7 7 847e87
8 7 7 847e87
9 7 7 847e87
10 7 7 847e87
11 7 7 847e87
12 7 7 847e87
13 7 7 847e87
14 7 7 847e87
15 7 7 847e87
2 8 7 847e87
3 8 7 847e87
4 8 7 847e87
5 8 7 847e87
6 8 7 847e87
7 8 7 847e87
8 8 7 847e87
9 8 7 847e87
10 8 7 847e87
11 8 7 847e87
12 8 7 847e87
13 8 7 847e87
14 8 7 847e87
15 8 7 847e87
2 9 7 847e87
3 9 7 847e87
4 9 7 847e87
5 9 7 847e87
6 9 7 847e87
7 9 7 847e87
8 9 7 847e87
9 9 7 847e87
10 9 7 847e87
11 9 7 847e87
12 9 7 847e87
13 9 7 847e87
14 9 7 847e87
15 9 7 847e87
2 10 7 847e87
3 10 7 847e87
4 10 7 847e87
5 10 7 847e87
6 10 7 847e87
7 10 7 847e87
8 10 7 847e87
9 10 7 847e87
10 10 7 847e87
11 10 7 847e87
12 10 7 847e87
13 10 7 847e87
14 10 7 847e87
15 10 7 847e87
2 11 7 847e87
3 11 7 847e87
4 11 7 847e87
5 11 7 847e87
6 11 7 847e87
7 11 7 847e87
8 11 7 847e87
9 11 7 847e87
10 11 7 847e87
11 11 7 847e87
12 11 7 847e87
13 11 7 847e87
14 11 7 847e87
15 11 7 847e87
2 12 7 847e87
3 12 7 847e87
4 12 7 847e87
5 12 7 847e87
6 12 7 847e87
7 12 7 847e87
8 12 7 847e87
9 12 7 847e87
10 12 7 847e87
11 12 7 847e87
12 12 7 847e87
13 12 7 847e87
14 12 7 847e87
15 12 7 847e87
2 13 7 847e87
3 13 7 847e87
4 13 7 847e87
5 13 7 847e87
6 13 7 847e87
7 13 7 847e87
8 13 7 847e87
9 13 7 847e87
10 13 7 847e87
11 13 7 847e87
12 13 7 847e87
13 13 7 847e87
14 13 7 847e87
15 13 7 847e87
2 14 7 847e87
3 14 7 847e87
4 14 7 847e87
5 14 7 847e87
6 14 7 847e87
7 14 7 847e87
8 14 7 847e87
9 14 7 847e87
10 14 7 847e87
11 14 7 847e87
12 14 7 847e87
13 14 7 847e87
14 14 7 847e87
15 14 7 847e87
2 15 7 847e87
3 15 7 847e87
4 15 7 847e87
5 15 7 847e87
6 15 7 847e87
7 15 7 847e87
8 15 7 847e87
9 15 7 847e87
10 15 7 847e87
11 15 7 847e87
12 15 7 847e87
13 15 7 847e87
14 15 7 847e87
15 15 7 847e87
6 0 8 ffffff
7 0 8 ffffff
8 0 8 ffffff
9 0 8 d77bba
10 0 8 d77bba
11 0 8 ffffff
12 0 8 ffffff
13 0 8 ffffff
0 1 8 696a6a
1 1 8 696a6a
2 1 8 847e87
3 1 8 847e87
4 1 8 847e87
5 1 8 847e87
6 1 8 847e87
7 1 8 847e87
8 1 8 847e87
9 1 8 847e87
10 1 8 847e87
11 1 8 847e87
12 1 8 847e87
13 1 8 847e87
14 1 8 847e87
15 1 8 847e87
2 2 8 847e87
3 2 8 847e87
4 2 8 847e87
5 2 8 847e87
6 2 8 847e87
7 2 8 847e87
8 2 8 847e87
9 2 8 847e87
10 2 8 847e87
11 2 8 847e87
12 2 8 847e87
13 2 8 847e87
14 2 8 847e87
15 2 8 847e87
2 3 8 847e87
3 3 8 847e87
4 3 8 847e87
5 3 8 847e87
6 3 8 847e87
7 3 8 847e87
8 3 8 847e87
9 3 8 847e87
10 3 8 847e87
11 3 8 847e87
12 3 8 847e87
13 3 8 847e87
14 3 8 847e87
15 3 8 847e87
2 4 8 847e87
3 4 8 847e87
4 4 8 847e87
5 4 8 847e87
6 4 8 847e87
7 4 8 847e87
8 4 8 847e87
9 4 8 847e87
10 4 8 847e87
11 4 8 847e87
12 4 8 847e87
13 4 8 847e87
14 4 8 847e87
15 4 8 847e87
2 5 8 847e87
3 5 8 847e87
4 5 8 847e87
5 5 8 847e87
6 5 8 847e87
7 5 8 847e87
8 5 8 847e87
9 5 8 847e87
10 5 8 847e87
11 5 8 847e87
12 5 8 847e87
13 5 8 847e87
14 5 8 847e87
15 5 8 847e87
2 6 8 847e87
3 6 8 847e87
4 6 8 847e87
5 6 8 847e87
6 6 8 847e87
7 6 8 847e87
8 6 8 847e87
9 6 8 847e87
10 6 8 847e87
11 6 8 847e87
12 6 8 847e87
13 6 8 847e87
14 6 8 847e87
15 6 8 847e87
2 7 8 847e87
3 7 8 847e87
4 7 8 847e87
5 7 8 847e87
6 7 8 847e87
7 7 8 847e87
8 7 8 847e87
9 7 8 847e87
10 7 8 847e87
11 7 8 847e87
12 7 8 847e87
13 7 8 847e87
14 7 8 847e87
15 7 8 847e87
2 8 8 847e87
3 8 8 847e87
4 8 8 847e87
5 8 8 847e87
6 8 8 847e87
7 8 8 847e87
8 8 8 847e87
9 8 8 847e87
10 8 8 847e87
11 8 8 847e87
12 8 8 847e87
13 8 8 847e87
14 8 8 847e87
15 8 8 847e87
2 9 8 847e87
3 9 8 847e87
4 9 8 847e87
5 9 8 847e87
6 9 8 847e87
7 9 8 847e87
8 9 8 847e87
9 9 8 847e87
10 9 8 847e87
11 9 8 847e87
12 9 8 847e87
13 9 8 847e87
14 9 8 847e87
15 9 8 847e87
2 10 8 847e87
3 10 8 847e87
4 10 8 847e87
5 10 8 847e87
6 10 8 847e87
7 10 8 847e87
8 10 8 847e87
9 10 8 847e87
10 10 8 847e87
11 10 8 847e87
12 10 8 847e87
13 10 8 847e87
14 10 8 847e87
15 10 8 847e87
2 11 8 847e87
3 11 8 847e87
4 11 8 847e87
5 11 8 847e87
6 11 8 847e87
7 11 8 847e87
8 11 8 847e87
9 11 8 847e87
10 11 8 847e87
11 11 8 847e87
12 11 8 847e87
13 11 8 847e87
14 11 8 847e87
15 11 8 847e87
2 12 8 847e87
3 12 8 847e87
4 12 8 847e87
5 12 8 847e87
6 12 8 847e87
7 12 8 847e87
8 12 8 847e87
9 12 8 847e87
10 12 8 847e87
11 12 8 847e87
12 12 8 847e87
13 12 8 847e87
14 12 8 847e87
15 12 8 847e87
2 13 8 847e87
3 13 8 847e87
4 13 8 847e87
5 13 8 847e87
6 13 8 847e87
7 13 8 847e87
8 13 8 847e87
9 13 8 847e87
10 13 8 847e87
11 13 8 847e87
12 13 8 847e87
13 13 8 847e87
14 13 8 847e87
15 13 8 847e87
2 14 8 847e87
3 14 8 847e87
4 14 8 847e87
5 14 8 847e87
6 14 8 847e87
7 14 8 847e87
8 14 8 847e87
9 14 8 847e87
10 14 8 847e87
11 14 8 847e87
12 14 8 847e87
13 14 8 847e87
14 14 8 847e87
15 14 8 847e87
2 15 8 847e87
3 15 8 847e87
4 15 8 847e87
5 15 8 847e87
6 15 8 847e87
7 15 8 847e87
8 15 8 847e87
9 15 8 847e87
10 15 8 847e87
11 15 8 847e87
12 15 8 847e87
13 15 8 847e87
14 15 8 847e87
15 15 8 847e87
2 1 9 847e87
3 1 9 847e87
4 1 9 fbf236
5 1 9 fbf236
6 1 9 fbf236
7 1 9 fbf236
8 1 9 847e87
9 1 9 847e87
10 1 9 847e87
11 1 9 847e87
12 1 9 fbf236
13 1 9 fbf236
14 1 9 fbf236
15 1 9 fbf236
2 2 9 847e87
3 2 9 847e87
4 2 9 847e87
5 2 9 847e87
6 2 9 847e87
7 2 9 847e87
8 2 9 847e87
9 2 9 847e87
10 2 9 847e87
11 2 9 847e87
12 2 9 847e87
13 2 9 847e87
14 2 9 847e87
15 2 9 847e87
2 3 9 847e87
3 3 9 847e87
4 3 9 847e87
5 3 9 847e87
6 3 9 847e87
7 3 9 847e87
8 3 9 847e87
9 3 9 847e87
10 3 9 847e87
11 3 9 847e87
12 3 9 847e87
13 3 9 847e87
14 3 9 847e87
15 3 9 847e87
2 4 9 847e87
3 4 9 847e87
4 4 9 847e87
5 4 9 847e87
6 4 9 847e87
7 4 9 847e87
8 4 9 847e87
9 4 9 847e87
10 4 9 847e87
11 4 9 847e87
12 4 9 847e87
13 4 9 847e87
14 4 9 847e87
15 4 9 847e87
2 5 9 847e87
3 5 9 847e87
4 5 9 847e87
5 5 9 847e87
6 5 9 847e87
7 5 9 847e87
8 5 9 847e87
9 5 9 847e87
10 5 9 847e87
11 5 9 847e87
12 5 9 847e87
13 5 9 847e87
14 5 9 847e87
15 5 9 847e87
2 6 9 847e87
3 6 9 847e87
4 6 9 847e87
5 6 9 847e87
6 6 9 847e87
7 6 9 847e87
8 6 9 847e87
9 6 9 847e87
10 6 9 847e87
11 6 9 847e87
12 6 9 847e87
13 6 9 847e87
14 6 9 847e87
15 6 9 847e87
2 7 9 847e87
3 7 9 847e87
4 7 9 847e87
5 7 9 847e87
6 7 9 847e87
7 7 9 847e87
8 7 9 847e87
9 7 9 847e87
10 7 9 847e87
11 7 9 847e87
12 7 9 847e87
13 7 9 847e87
14 7 9 847e87
15 7 9 847e87
2 8 9 847e87
3 8 9 847e87
4 8 9 847e87
5 8 9 847e87
6 8 9 847e87
7 8 9 847e87
8 8 9 847e87
9 8 9 847e87
10 8 9 847e87
11 8 9 847e87
12 8 9 847e87
13 8 9 847e87
14 8 9 847e87
15 8 9 847e87
2 9 9 847e87
3 9 9 847e87
4 9 9 847e87
5 9 9 847e87
6 9 9 847e87
7 9 9 847e87
8 9 9 847e87
9 9 9 847e87
10 9 9 847e87
11 9 9 847e87
12 9 9 847e87
13 9 9 847e87
14 9 9 847e87
15 9 9 847e87
2 10 9 847e87
3 10 9 847e87
4 10 9 847e87
5 10 9 847e87
6 10 9 847e87
7 10 9 847e87
8 10 9 847e87
9 10 9 847e87
10 10 9 847e87
11 10 9 847e87
12 10 9 847e87
13 10 9 847e87
14 10 9 847e87
15 10 9 847e87
2 11 9 847e87
3 11 9 847e87
4 11 9 847e87
5 11 9 847e87
6 11 9 847e87
7 11 9 847e87
8 11 9 847e87
9 11 9 847e87
10 11 9 847e87
11 11 9 847e87
12 11 9 847e87
13 11 9 847e87
14 11 9 847e87
15 11 9 847e87
2 12 9 847e87
3 12 9 847e87
4 12 9 847e87
5 12 9 847e87
6 12 9 847e87
7 12 9 847e87
8 12 9 847e87
9 12 9 847e87
10 12 9 847e87
11 12 9 847e87
12 12 9 847e87
13 12 9 847e87
14 12 9 847e87
15 12 9 847e87
2 13 9 847e87
3 13 9 847e87
4 13 9 847e87
5 13 9 847e87
6 13 9 847e87
7 13 9 847e87
8 13 9 847e87
9 13 9 847e87
10 13 9 847e87
11 13 9 847e87
12 13 9 847e87
13 13 9 847e87
14 13 9 847e87
15 13 9 847e87
2 14 9 847e87
3 14 9 847e87
4 14 9 847e87
5 14 9 847e87
6 14 9 847e87
7 14 9 847e87
8 14 9 847e87
9 14 9 847e87
10 14 9 847e87
11 14 9 847e87
12 14 9 847e87
13 14 9 847e87
14 14 9 847e87
15 14 9 847e87
2 15 9 847e87
3 15 9 847e87
4 15 9 847e87
5 15 9 847e87
6 15 9 847e87
7 15 9 847e87
8 15 9 847e87
9 15 9 847e87
10 15 9 847e87
11 15 9 847e87
12 15 9 847e87
13 15 9 847e87
14 15 9 847e87
15 15 9 847e87
2 1 10 847e87
3 1 10 847e87
4 1 10 fbf236
5 1 10 222034
6 1 10 222034
7 1 10 222034
8 1 10 847e87
9 1 10 847e87
10 1 10 847e87
11 1 10 847e87
12 1 10 fbf236
13 1 10 222034
14 1 10 222034
15 1 10 222034
2 2 10 847e87
3 2 10 847e87
4 2 10 847e87
5 2 10 847e87
6 2 10 847e87
7 2 10 847e87
8 2 10 847e87
9 2 10 847e87
10 2 10 847e87
11 2 10 847e87
12 2 10 847e87
13 2 10 847e87
14 2 10 847e87
15 2 10 847e87
2 3 10 847e87
3 3 10 847e87
4 3 10 847e87
5 3 10 847e87
6 3 10 847e87
7 3 10 847e87
8 3 10 847e87
9 3 10 847e87
10 3 10 847e87
11 3 10 847e87
12 3 10 847e87
13 3 10 847e87
14 3 10 847e87
15 3 10 847e87
2 4 10 847e87
3 4 10 847e87
4 4 10 847e87
5 4 10 847e87
6 4 10 847e87
7 4 10 847e87
8 4 10 847e87
9 4 10 847e87
10 4 10 847e87
11 4 10 847e87
12 4 10 847e87
13 4 10 847e87
14 4 10 847e87
15 4 10 847e87
2 5 10 847e87
3 5 10 847e87
4 5 10 847e87
5 5 10 847e87
6 5 10 847e87
7 5 10 847e87
8 5 10 847e87
9 5 10 847e87
10 5 10 847e87
11 5 10 847e87
12 5 10 847e87
13 5 10 847e87
14 5 10 847e87
15 5 10 847e87
2 6 10 847e87
3 6 10 847e87
4 6 10 847e87
5 6 10 847e87
6 6 10 847e87
7 6 10 847e87
8 6 10 847e87
9 6 10 847e87
10 6 10 847e87
11 6 10 847e87
12 6 10 847e87
13 6 10 847e87
14 6 10 847e87
15 6 10 847e87
2 7 10 847e87
3 7 10 847e87
4 7 10 847e87
5 7 10 847e87
6 7 10 847e87
7 7 10 847e87
8 7 10 847e87
9 7 10 847e87
10 7 10 847e87
11 7 10 847e87
12 7 10 847e87
13 7 10 847e87
14 7 10 847e87
15 7 10 847e87
2 8 10 847e87
3 8 10 847e87
4 8 10 847e87
5 8 10 847e87
6 8 10 847e87
7 8 10 847e87
8 8 10 847e87
9 8 10 847e87
10 8 10 847e87
11 8 10 847e87
12 8 10 847e87
13 8 10 847e87
14 8 10 847e87
15 8 10 847e87
2 9 10 847e87
3 9 10 847e87
4 9 10 847e87
5 9 10 847e87
6 9 10 847e87
7 9 10 847e87
8 9 10 847e87
9 9 10 847e87
10 9 10 847e87
11 9 10 847e87
12 9 10 847e87
13 9 10 847e87
14 9 10 847e87
15 9 10 847e87
2 10 10 847e87
3 10 10 847e87
4 10 10 847e87
5 10 10 847e87
6 10 10 847e87
7 10 10 847e87
8 10 10 847e87
9 10 10 847e87
10 10 10 847e87
11 10 10 847e87
12 10 10 847e87
13 10 10 847e87
14 10 10 847e87
15 10 10 847e87
2 11 10 847e87
3 11 10 847e87
4 11 10 847e87
5 11 10 847e87
6 11 10 847e87
7 11 10 847e87
8 11 10 847e87
9 11 10 847e87
10 11 10 847e87
11 11 10 847e87
12 11 10 847e87
13 11 10 847e87
14 11 10 847e87
15 11 10 847e87
2 12 10 847e87
3 12 10 847e87
4 12 10 847e87
5 12 10 847e87
6 12 10 847e87
7 12 10 847e87
8 12 10 847e87
9 12 10 847e87
10 12 10 847e87
11 12 10 847e87
12 12 10 847e87
13 12 10 847e87
14 12 10 847e87
15 12 10 847e87
2 13 10 847e87
3 13 10 847e87
4 13 10 847e87
5 13 10 847e87
6 13 10 847e87
7 13 10 847e87
8 13 10 847e87
9 13 10 847e87
10 13 10 847e87
11 13 10 847e87
12 13 10 847e87
13 13 10 847e87
14 13 10 847e87
15 13 10 847e87
2 14 10 847e87
3 14 10 847e87
4 14 10 847e87
5 14 10 847e87
6 14 10 847e87
7 14 10 847e87
8 14 10 847e87
9 14 10 847e87
10 14 10 847e87
11 14 10 847e87
12 14 10 847e87
13 14 10 847e87
14 14 10 847e87
15 14 10 847e87
2 15 10 847e87
3 15 10 847e87
4 15 10 847e87
5 15 10 847e87
6 15 10 847e87
7 15 10 847e87
8 15 10 847e87
9 15 10 847e87
10 15 10 847e87
11 15 10 847e87
12 15 10 847e87
13 15 10 847e87
14 15 10 847e87
15 15 10 847e87
2 1 11 847e87
3 1 11 847e87
4 1 11 fbf236
5 1 11 222034
6 1 11 222034
7 1 11 222034
8 1 11 847e87
9 1 11 847e87
10 1 11 847e87
11 1 11 847e87
12 1 11 fbf236
13 1 11 222034
14 1 11 222034
15 1 11 222034
2 2 11 847e87
3 2 11 847e87
4 2 11 847e87
5 2 11 847e87
6 2 11 847e87
7 2 11 847e87
8 2 11 847e87
9 2 11 847e87
10 2 11 847e87
11 2 11 847e87
12 2 11 847e87
13 2 11 847e87
14 2 11 847e87
15 2 11 847e87
2 3 11 847e87
3 3 11 847e87
4 3 11 847e87
5 3 11 847e87
6 3 11 847e87
7 3 11 847e87
8 3 11 847e87
9 3 11 847e87
10 3 11 847e87
11 3 11 847e87
12 3 11 847e87
13 3 11 847e87
14 3 11 847e87
15 3 11 847e87
2 4 11 847e87
3 4 11 847e87
4 4 11 847e87
5 4 11 847e87
6 4 11 847e87
7 4 11 847e87
8 4 11 847e87
9 4 11 847e87
10 4 11 847e87
11 4 11 847e87
12 4 11 847e87
13 4 11 847e87
14 4 11 847e87
15 4 11 847e87
2 5 11 847e87
3 5 11 847e87
4 5 11 847e87
5 5 11 847e87
6 5 11 847e87
7 5 11 847e87
8 5 11 847e87
9 5 11 847e87
10 5 11 847e87
11 5 11 847e87
12 5 11 847e87
13 5 11 847e87
14 5 11 847e87
15 5 11 847e87
2 6 11 847e87
3 6 11 847e87
4 6 11 847e87
5 6 11 847e87
6 6 11 847e87
7 6 11 847e87
8 6 11 847e87
9 6 11 847e87
10 6 11 847e87
11 6 11 847e87
12 6 11 847e87
13 6 11 847e87
14 6 11 847e87
15 6 11 847e87
2 7 11 847e87
3 7 11 847e87
4 7 11 847e87
5 7 11 847e87
6 7 11 847e87
7 7 11 847e87
8 7 11 847e87
9 7 11 847e87
10 7 11 847e87
11 7 11 847e87
12 7 11 847e87
13 7 11 847e87
14 7 11 847e87
15 7 11 847e87
2 8 11 847e87
3 8 11 847e87
4 8 11 847e87
5 8 11 847e87
6 8 11 847e87
7 8 11 847e87
8 8 11 847e87
9 8 11 847e87
10 8 11 847e87
11 8 11 847e87
12 8 11 847e87
13 8 11 847e87
14 8 11 847e87
15 8 11 847e87
2 9 11 847e87
3 9 11 847e87
4 9 11 847e87
5 9 11 847e87
6 9 11 847e87
7 9 11 847e87
8 9 11 847e87
9 9 11 847e87
10 9 11 847e87
11 9 11 847e87
12 9 11 847e87
13 9 11 847e87
14 9 11 847e87
15 9 11 847e87
2 10 11 847e87
3 10 11 847e87
4 10 11 847e87
5 10 11 847e87
6 10 11 847e87
7 10 11 847e87
8 10 11 847e87
9 10 11 847e87
10 10 11 847e87
11 10 11 847e87
12 10 11 847e87
13 10 11 847e87
14 10 11 847e87
15 10 11 847e87
2 11 11 847e87
3 11 11 847e87
4 11 11 847e87
5 11 11 847e87
6 11 11 847e87
7 11 11 847e87
8 11 11 847e87
9 11 11 847e87
10 11 11 847e87
11 11 11 847e87
12 11 11 847e87
13 11 11 847e87
14 11 11 847e87
15 11 11 847e87
2 12 11 847e87
3 12 11 847e87
4 12 11 847e87
5 12 11 847e87
6 12 11 847e87
7 12 11 847e87
8 12 11 847e87
9 12 11 847e87
10 12 11 847e87
11 12 11 847e87
12 12 11 847e87
13 12 11 847e87
14 12 11 847e87
15 12 11 847e87
2 13 11 847e87
3 13 11 847e87
4 13 11 847e87
5 13 11 847e87
6 13 11 847e87
7 13 11 847e87
8 13 11 847e87
9 13 11 847e87
10 13 11 847e87
11 13 11 847e87
12 13 11 847e87
13 13 11 847e87
14 13 11 847e87
15 13 11 847e87
2 14 11 847e87
3 14 11 847e87
4 14 11 847e87
5 14 11 847e87
6 14 11 847e87
7 14 11 847e87
8 14 11 847e87
9 14 11 847e87
10 14 11 847e87
11 14 11 847e87
12 14 11 847e87
13 14 11 847e87
14 14 11 847e87
15 14 11 847e87
2 15 11 847e87
3 15 11 847e87
4 15 11 847e87
5 15 11 847e87
6 15 11 847e87
7 15 11 847e87
8 15 11 847e87
9 15 11 847e87
10 15 11 847e87
11 15 11 847e87
12 15 11 847e87
13 15 11 847e87
14 15 11 847e87
15 15 11 847e87
2 1 12 847e87
3 1 12 847e87
4 1 12 fbf236
5 1 12 222034
6 1 12 222034
7 1 12 ffffff
8 1 12 847e87
9 1 12 847e87
10 1 12 847e87
11 1 12 847e87
12 1 12 fbf236
13 1 12 222034
14 1 12 222034
15 1 12 ffffff
2 2 12 847e87
3 2 12 847e87
4 2 12 847e87
5 2 12 847e87
6 2 12 847e87
7 2 12 847e87
8 2 12 847e87
9 2 12 847e87
10 2 12 847e87
11 2 12 847e87
12 2 12 847e87
13 2 12 847e87
14 2 12 847e87
15 2 12 847e87
2 3 12 847e87
3 3 12 847e87
4 3 12 847e87
5 3 12 847e87
6 3 12 847e87
7 3 12 847e87
8 3 12 847e87
9 3 12 847e87
10 3 12 847e87
11 3 12 847e87
12 3 12 847e87
13 3 12 847e87
14 3 12 847e87
15 3 12 847e87
2 4 12 847e87
3 4 12 847e87
4 4 12 847e87
5 4 12 847e87
6 4 12 847e87
7 4 12 847e87
8 4 12 847e87
9 4 12 847e87
10 4 12 847e87
11 4 12 847e87
12 4 12 847e87
13 4 12 847e87
14 4 12 847e87
15 4 12 847e87
2 5 12 847e87
3 5 12 847e87
4 5 12 847e87
5 5 12 847e87
6 5 12 847e87
7 5 12 847e87
8 5 12 847e87
9 5 12 847e87
10 5 12 847e87
11 5 12 847e87
12 5 12 847e87
13 5 12 847e87
14 5 12 847e87
15 5 12 847e87
2 6 12 847e87
3 6 12 847e87
4 6 12 847e87
5 6 12 847e87
6 6 12 847e87
7 6 12 847e87
8 6 12 847e87
9 6 12 847e87
10 6 12 847e87
11 6 12 847e87
12 6 12 847e87
13 6 12 847e87
14 6 12 847e87
15 6 12 847e87
2 7 12 847e87
3 7 12 847e87
4 7 12 847e87
5 7 12 847e87
6 7 12 847e87
7 7 12 847e87
8 7 12 847e87
9 7 12 847e87
10 7 12 847e87
11 7 12 847e87
12 7 12 847e87
13 7 12 847e87
14 7 12 847e87
15 7 12 847e87
2 8 12 847e87
3 8 12 847e87
4 8 12 847e87
5 8 12 847e87
6 8 12 847e87
7 8 12 847e87
8 8 12 847e87
9 8 12 847e87
10 8 12 847e87
11 8 12 847e87
12 8 12 847e87
13 8 12 847e87
14 8 12 847e87
15 8 12 847e87
2 9 12 847e87
3 9 12 847e87
4 9 12 847e87
5 9 12 847e87
6 9 12 847e87
7 9 12 847e87
8 9 12 847e87
9 9 12 847e87
10 9 12 847e87
11 9 12 847e87
12 9 12 847e87
13 9 12 847e87
14 9 12 847e87
15 9 12 847e87
2 10 12 847e87
3 10 12 847e87
4 10 12 847e87
5 10 12 847e87
6 10 12 847e87
7 10 12 847e87
8 10 12 847e87
9 10 12 847e87
10 10 12 847e87
11 10 12 847e87
12 10 12 847e87
13 10 12 847e87
14 10 12 847e87
15 10 12 847e87
2 11 12 847e87
3 11 12 847e87
4 11 12 847e87
5 11 12 847e87
6 11 12 847e87
7 11 12 847e87
8 11 12 847e87
9 11 12 847e87
10 11 12 847e87
11 11 12 847e87
12 11 12 847e87
13 11 12 847e87
14 11 12 847e87
15 11 12 847e87
2 12 12 847e87
3 12 12 847e87
4 12 12 847e87
5 12 12 847e87
6 12 12 847e87
7 12 12 847e87
8 12 12 847e87
9 12 12 847e87
10 12 12 847e87
11 12 12 847e87
12 12 12 847e87
13 12 12 847e87
14 12 12 847e87
15 12 12 847e87
2 13 12 847e87
3 13 12 847e87
4 13 12 847e87
5 13 12 847e87
6 13 12 847e87
7 13 12 847e87
8 13 12 847e87
9 13 12 847e87
10 13 12 847e87
11 13 12 847e87
12 13 12 847e87
13 13 12 847e87
14 13 12 847e87
15 13 12 847e87
2 14 12 847e87
3 14 12 847e87
4 14 12 847e87
5 14 12 847e87
6 14 12 847e87
7 14 12 847e87
8 14 12 847e87
9 14 12 847e87
10 14 12 847e87
11 14 12 847e87
12 14 12 847e87
13 14 12 847e87
14 14 12 847e87
15 14 12 847e87
2 15 12 847e87
3 15 12 847e87
4 15 12 847e87
5 15 12 847e87
6 15 12 847e87
7 15 12 847e87
8 15 12 847e87
9 15 12 847e87
10 15 12 847e87
11 15 12 847e87
12 15 12 847e87
13 15 12 847e87
14 15 12 847e87
15 15 12 847e87
2 1 13 847e87
3 1 13 847e87
4 1 13 847e87
5 1 13 847e87
6 1 13 847e87
7 1 13 847e87
8 1 13 847e87
9 1 13 847e87
10 1 13 847e87
11 1 13 847e87
12 1 13 847e87
13 1 13 847e87
14 1 13 847e87
15 1 13 847e87
2 2 13 847e87
3 2 13 847e87
4 2 13 847e87
5 2 13 847e87
6 2 13 847e87
7 2 13 847e87
8 2 13 847e87
9 2 13 847e87
10 2 13 847e87
11 2 13 847e87
12 2 13 847e87
13 2 13 847e87
14 2 13 847e87
15 2 13 847e87
2 3 13 847e87
3 3 13 847e87
4 3 13 847e87
5 3 13 847e87
6 3 13 847e87
7 3 13 847e87
8 3 13 847e87
9 3 13 847e87
10 3 13 847e87
11 3 13 847e87
12 3 13 847e87
13 3 13 847e87
14 3 13 847e87
15 3 13 847e87
2 4 13 847e87
3 4 13 847e87
4 4 13 847e87
5 4 13 847e87
6 4 13 847e87
7 4 13 847e87
8 4 13 847e87
9 4 13 847e87
10 4 13 847e87
11 4 13 847e87
12 4 13 847e87
13 4 13 847e87
14 4 13 847e87
15 4 13 847e87
2 5 13 847e87
3 5 13 847e87
4 5 13 847e87
5 5 13 847e87
6 5 13 847e87
7 5 13 847e87
8 5 13 847e87
9 5 13 847e87
10 5 13 847e87
11 5 13 847e87
12 5 13 847e87
13 5 13 847e87
14 5 13 847e87
15 5 13 847e87
2 6 13 847e87
3 6 13 847e87
4 6 13 847e87
5 6 13 847e87
6 6 13 847e87
7 6 13 847e87
8 6 13 847e87
9 6 13 847e87
10 6 13 847e87
11 6 13 847e87
12 6 13 847e87
13 6 13 847e87
14 6 13 847e87
15 6 13 847e87
2 7 13 847e87
3 7 13 847e87
4 7 13 847e87
5 7 13 847e87
6 7 13 847e87
7 7 13 847e87
8 7 13 847e87
9 7 13 847e87
10 7 13 847e87
11 7 13 847e87
12 7 13 847e87
13 7 13 847e87
14 7 13 847e87
15 7 13 847e87
2 8 13 847e87
3 8 13 847e87
4 8 13 847e87
5 8 13 847e87
6 8 13 847e87
7 8 13 847e87
8 8 13 847e87
9 8 13 847e87
10 8 13 847e87
11 8 13 847e87
12 8 13 847e87
13 8 13 847e87
14 8 13 847e87
15 8 13 847e87
2 9 13 847e87
3 9 13 847e87
4 9 13 847e87
5 9 13 847e87
6 9 13 847e87
7 9 13 847e87
8 9 13 847e87
9 9 13 847e87
10 9 13 847e87
11 9 13 847e87
12 9 13 847e87
13 9 13 847e87
14 9 13 847e87
15 9 13 847e87
2 10 13 847e87
3 10 13 847e87
4 10 13 847e87
5 10 13 847e87
6 10 13 847e87
7 10 13 847e87
8 10 13 847e87
9 10 13 847e87
10 10 13 847e87
11 10 13 847e87
12 10 13 847e87
13 10 13 847e87
14 10 13 847e87
15 10 13 847e87
2 11 13 847e87
3 11 13 847e87
4 11 13 847e87
5 11 13 847e87
6 11 13 847e87
7 11 13 847e87
8 11 13 847e87
9 11 13 847e87
10 11 13 847e87
11 11 13 847e87
12 11 13 847e87
13 11 13 847e87
14 11 13 847e87
15 11 13 847e87
2 12 13 847e87
3 12 13 847e87
4 12 13 847e87
5 12 13 847e87
6 12 13 847e87
7 12 13 847e87
8 12 13 847e87
9 12 13 847e87
10 12 13 847e87
11 12 13 847e87
12 12 13 847e87
13 12 13 847e87
14 12 13 847e87
15 12 13 847e87
2 13 13 847e87
3 13 13 847e87
4 13 13 847e87
5 13 13 847e87
6 13 13 847e87
7 13 13 847e87
8 13 13 847e87
9 13 13 847e87
10 13 13 847e87
11 13 13 847e87
12 13 13 847e87
13 13 13 847e87
14 13 13 847e87
15 13 13 847e87
2 14 13 847e87
3 14 13 847e87
4 14 13 847e87
5 14 13 847e87
6 14 13 847e87
7 14 13 847e87
8 14 13 847e87
9 14 13 847e87
10 14 13 847e87
11 14 13 847e87
12 14 13 847e87
13 14 13 847e87
14 14 13 847e87
15 14 13 847e87
2 15 13 847e87
3 15 13 847e87
4 15 13 847e87
5 15 13 847e87
6 15 13 847e87
7 15 13 847e87
8 15 13 847e87
9 15 13 847e87
10 15 13 847e87
11 15 13 847e87
12 15 13 847e87
13 15 13 847e87
14 15 13 847e87
15 15 13 847e87
2 1 14 847e87
3 1 14 847e87
4 1 14 847e87
5 1 14 847e87
6 1 14 847e87
7 1 14 847e87
8 1 14 847e87
9 1 14 847e87
10 1 14 847e87
11 1 14 847e87
12 1 14 847e87
13 1 14 847e87
14 1 14 847e87
15 1 14 847e87
2 2 14 847e87
3 2 14 847e87
4 2 14 847e87
5 2 14 847e87
6 2 14 847e87
7 2 14 847e87
8 2 14 847e87
9 2 14 847e87
10 2 14 847e87
11 2 14 847e87
12 2 14 847e87
13 2 14 847e87
14 2 14 847e87
15 2 14 847e87
2 3 14 847e87
3 3 14 847e87
4 3 14 847e87
5 3 14 847e87
6 3 14 847e87
7 3 14 847e87
8 3 14 847e87
9 3 14 847e87
10 3 14 847e87
11 3 14 847e87
12 3 14 847e87
13 3 14 847e87
14 3 14 847e87
15 3 14 847e87
2 4 14 847e87
3 4 14 847e87
4 4 14 847e87
5 4 14 847e87
6 4 14 847e87
7 4 14 847e87
8 4 14 847e87
9 4 14 847e87
10 4 14 847e87
11 4 14 847e87
12 4 14 847e87
13 4 14 847e87
14 4 14 847e87
15 4 14 847e87
2 5 14 847e87
3 5 14 847e87
4 5 14 847e87
5 5 14 847e87
6 5 14 847e87
7 5 14 847e87
8 5 14 847e87
9 5 14 847e87
10 5 14 847e87
11 5 14 847e87
12 5 14 847e87
13 5 14 847e87
14 5 14 847e87
15 5 14 847e87
2 6 14 847e87
3 6 14 847e87
4 6 14 847e87
5 6 14 847e87
6 6 14 847e87
7 6 14 847e87
8 6 14 847e87
9 6 14 847e87
10 6 14 847e87
11 6 14 847e87
12 6 14 847e87
13 6 14 847e87
14 6 14 847e87
15 6 14 847e87
2 7 14 847e87
3 7 14 847e87
4 7 14 847e87
5 7 14 847e87
6 7 14 847e87
7 7 14 847e87
8 7 14 847e87
9 7 14 847e87
10 7 14 847e87
11 7 14 847e87
12 7 14 847e87
13 7 14 847e87
14 7 14 847e87
15 7 14 847e87
2 8 14 847e87
3 8 14 847e87
4 8 14 847e87
5 8 14 847e87
6 8 14 847e87
7 8 14 847e87
8 8 14 847e87
9 8 14 847e87
10 8 14 847e87
11 8 14 847e87
12 8 14 847e87
13 8 14 847e87
14 8 14 847e87
15 8 14 847e87
2 9 14 847e87
3 9 14 847e87
4 9 14 847e87
5 9 14 847e87
6 9 14 847e87
7 9 14 847e87
8 9 14 847e87
9 9 14 847e87
10 9 14 847e87
11 9 14 847e87
12 9 14 847e87
13 9 14 847e87
14 9 14 847e87
15 9 14 847e87
2 10 14 847e87
3 10 14 847e87
4 10 14 847e87
5 10 14 847e87
6 10 14 847e87
7 10 14 847e87
8 10 14 847e87
9 10 14 847e87
10 10 14 847e87
11 10 14 847e87
12 10 14 847e87
13 10 14 847e87
14 10 14 847e87
15 10 14 847e87
2 11 14 847e87
3 11 14 847e87
4 11 14 847e87
5 11 14 847e87
6 11 14 847e87
7 11 14 847e87
8 11 14 847e87
9 11 14 847e87
10 11 14 847e87
11 11 14 847e87
12 11 14 847e87
13 11 14 847e87
14 11 14 847e87
15 11 14 847e87
2 12 14 847e87
3 12 14 847e87
4 12 14 847e87
5 12 14 847e87
6 12 14 847e87
7 12 14 847e87
8 12 14 847e87
9 12 14 847e87
10 12 14 847e87
11 12 14 847e87
12 12 14 847e87
13 12 14 847e87
14 12 14 847e87
15 12 14 847e87
2 13 14 847e87
3 13 14 847e87
4 13 14 847e87
5 13 14 847e87
6 13 14 847e87
7 13 14 847e87
8 13 14 847e87
9 13 14 847e87
10 13 14 847e87
11 13 14 847e87
12 13 14 847e87
13 13 14 847e87
14 13 14 847e87
15 13 14 847e87
2 14 14 847e87
3 14 14 847e87
4 14 14 847e87
5 14 14 847e87
6 14 14 847e87
7 14 14 847e87
8 14 14 847e87
9 14 14 847e87
10 14 14 847e87
11 14 14 847e87
12 14 14 847e87
13 14 14 847e87
14 14 14 847e87
15 14 14 847e87
2 15 14 847e87
3 15 14 847e87
4 15 14 847e87
5 15 14 847e87
6 15 14 847e87
7 15 14 847e87
8 15 14 847e87
9 15 14 847e87
10 15 14 847e87
11 15 14 847e87
12 15 14 847e87
13 15 14 847e87
14 15 14 847e87
15 15 14 847e87
2 1 15 847e87
3 1 15 847e87
4 1 15 847e87
5 1 15 847e87
6 1 15 847e87
7 1 15 847e87
8 1 15 847e87
9 1 15 847e87
10 1 15 847e87
11 1 15 847e87
12 1 15 847e87
13 1 15 847e87
14 1 15 847e87
15 1 15 847e87
2 2 15 847e87
3 2 15 847e87
4 2 15 847e87
5 2 15 847e87
6 2 15 847e87
7 2 15 847e87
8 2 15 847e87
9 2 15 847e87
10 2 15 847e87
11 2 15 847e87
12 2 15 847e87
13 2 15 847e87
14 2 15 847e87
15 2 15 847e87
2 3 15 847e87
3 3 15 847e87
4 3 15 847e87
5 3 15 847e87
6 3 15 847e87
7 3 15 847e87
8 3 15 847e87
9 3 15 847e87
10 3 15 847e87
11 3 15 847e87
12 3 15 847e87
13 3 15 847e87
14 3 15 847e87
15 3 15 847e87
2 4 15 847e87
3 4 15 847e87
4 4 15 847e87
5 4 15 847e87
6 4 15 847e87
7 4 15 847e87
8 4 15 847e87
9 4 15 847e87
10 4 15 847e87
11 4 15 847e87
12 4 15 847e87
13 4 15 847e87
14 4 15 847e87
15 4 15 847e87
2 5 15 847e87
3 5 15 847e87
4 5 15 847e87
5 5 15 847e87
6 5 15 847e87
7 5 15 847e87
8 5 15 847e87
9 5 15 847e87
10 5 15 847e87
11 5 15 847e87
12 5 15 847e87
13 5 15 847e87
14 5 15 847e87
15 5 15 847e87
2 6 15 847e87
3 6 15 847e87
4 6 15 847e87
5 6 15 696a6a
6 6 15 696a6a
7 6 15 696a6a
8 6 15 696a6a
9 6 15 696a6a
10 6 15 696a6a
11 6 15 696a6a
12 6 15 696a6a
13 6 15 696a6a
14 6 15 696a6a
15 6 15 847e87
2 7 15 847e87
3 7 15 847e87
4 7 15 847e87
5 7 15 696a6a
6 7 15 696a6a
7 7 15 696a6a
8 7 15 696a6a
9 7 15 696a6a
10 7 15 696a6a
11 7 15 696a6a
12 7 15 696a6a
13 7 15 696a6a
14 7 15 696a6a
15 7 15 847e87
2 8 15 847e87
3 8 15 847e87
4 8 15 847e87
5 8 15 847e87
6 8 15 847e87
7 8 15 847e87
8 8 15 847e87
9 8 15 847e87
10 8 15 847e87
11 8 15 847e87
12 8 15 847e87
13 8 15 847e87
14 8 15 847e87
15 8 15 847e87
2 9 15 847e87
3 9 15 847e87
4 9 15 847e87
5 9 15 847e87
6 9 15 847e87
7 9 15 847e87
8 9 15 847e87
9 9 15 847e87
10 9 15 847e87
11 9 15 847e87
12 9 15 847e87
13 9 15 847e87
14 9 15 847e87
15 9 15 847e87
2 10 15 847e87
3 10 15 847e87
4 10 15 847e87
5 10 15 696a6a
6 10 15 696a6a
7 10 15 696a6a
8 10 15 696a6a
9 10 15 696a6a
10 10 15 696a6a
11 10 15 696a6a
12 10 15 696a6a
13 10 15 696a6a
14 10 15 696a6a
15 10 15 847e87
2 11 15 847e87
3 11 15 847e87
4 11 15 847e87
5 11 15 696a6a
6 11 15 696a6a
7 11 15 696a6a
8 11 15 696a6a
9 11 15 696a6a
10 11 15 696a6a
11 11 15 696a6a
12 11 15 696a6a
13 11 15 696a6a
14 11 15 696a6a
15 11 15 847e87
2 12 15 847e87
3 12 15 847e87
4 12 15 847e87
5 12 15 847e87
6 12 15 847e87
7 12 15 847e87
8 12 15 847e87
9 12 15 847e87
10 12 15 847e87
11 12 15 847e87
12 12 15 847e87
13 12 15 847e87
14 12 15 847e87
15 12 15 847e87
2 13 15 847e87
3 13 15 847e87
4 13 15 847e87
5 13 15 847e87
6 13 15 847e87
7 13 15 847e87
8 13 15 847e87
9 13 15 847e87
10 13 15 847e87
11 13 15 847e87
12 13 15 847e87
13 13 15 847e87
14 13 15 847e87
15 13 15 847e87
2 14 15 847e87
3 14 15 847e87
4 14 15 847e87
5 14 15 696a6a
6 14 15 696a6a
7 14 15 696a6a
8 14 15 696a6a
9 14 15 696a6a
10 14 15 696a6a
11 14 15 696a6a
12 14 15 696a6a
13 14 15 696a6a
14 14 15 696a6a
15 14 15 847e87
2 15 15 847e87
3 15 15 847e87
4 15 15 847e87
5 15 15 696a6a
6 15 15 696a6a
7 15 15 696a6a
8 15 15 696a6a
9 15 15 696a6a
10 15 15 696a6a
11 15 15 696a6a
12 15 15 696a6a
13 15 15 696a6a
14 15 15 696a6a
15 15 15 847e87
16 1 0 696a6a
17 1 0 696a6a
16 2 0 696a6a
17 2 0 696a6a
16 3 0 696a6a
17 3 0 696a6a
16 4 0 696a6a
17 4 0 696a6a
16 13 0 696a6a
17 13 0 696a6a
16 14 0 696a6a
17 14 0 696a6a
16 15 0 696a6a
17 15 0 696a6a
16 1 1 847e87
17 1 1 847e87
16 2 1 847e87
17 2 1 847e87
16 3 1 847e87
17 3 1 847e87
16 4 1 847e87
17 4 1 847e87
16 13 1 847e87
17 13 1 847e87
16 14 1 847e87
17 14 1 847e87
16 15 1 847e87
17 15 1 847e87
16 1 2 847e87
17 1 2 847e87
16 2 2 847e87
17 2 2 847e87
16 3 2 847e87
17 3 2 847e87
16 4 2 847e87
17 4 2 847e87
16 5 2 9badb7
17 5 2 9badb7
16 6 2 9badb7
17 6 2 9badb7
16 7 2 9badb7
17 7 2 9badb7
16 8 2 9badb7
17 8 2 9badb7
16 9 2 9badb7
17 9 2 9badb7
16 10 2 9badb7
17 10 2 9badb7
16 11 2 9badb7
17 11 2 9badb7
16 12 2 9badb7
17 12 2 9badb7
16 13 2 847e87
17 13 2 847e87
16 14 2 847e87
17 14 2 847e87
16 15 2 847e87
17 15 2 847e87
16 1 3 847e87
17 1 3 847e87
16 2 3 847e87
17 2 3 847e87
16 3 3 847e87
17 3 3 847e87
16 4 3 847e87
17 4 3 847e87
16 5 3 847e87
17 5 3 847e87
16 6 3 847e87
17 6 3 847e87
16 7 3 847e87
17 7 3 847e87
16 8 3 847e87
17 8 3 847e87
16 9 3 847e87
17 9 3 847e87
16 10 3 847e87
17 10 3 847e87
16 11 3 847e87
17 11 3 847e87
16 12 3 847e87
17 12 3 847e87
16 13 3 847e87
17 13 3 847e87
16 14 3 847e87
17 14 3 847e87
16 15 3 847e87
17 15 3 847e87
16 1 4 847e87
17 1 4 847e87
16 2 4 847e87
17 2 4 847e87
16 3 4 847e87
17 3 4 847e87
16 4 4 847e87
17 4 4 847e87
16 5 4 847e87
17 5 4 847e87
16 6 4 847e87
17 6 4 847e87
16 7 4 847e87
17 7 4 847e87
16 8 4 847e87
17 8 4 847e87
16 9 4 847e87
17 9 4 847e87
16 10 4 847e87
17 10 4 847e87
16 11 4 847e87
17 11 4 847e87
16 12 4 847e87
17 12 4 847e87
16 13 4 847e87
17 13 4 847e87
16 14 4 847e87
17 14 4 847e87
16 15 4 847e87
17 15 4 847e87
16 1 5 847e87
17 1 5 847e87
16 2 5 847e87
17 2 5 847e87
16 3 5 847e87
17 3 5 847e87
16 4 5 847e87
17 4 5 847e87
16 5 5 847e87
17 5 5 847e87
16 6 5 847e87
17 6 5 847e87
16 7 5 847e87
17 7 5 847e87
16 8 5 847e87
17 8 5 847e87
16 9 5 847e87
17 9 5 847e87
16 10 5 847e87
17 10 5 847e87
16 11 5 847e87
17 11 5 847e87
16 12 5 847e87
17 12 5 847e87
16 13 5 847e87
17 13 5 847e87
16 14 5 847e87
17 14 5 847e87
16 15 5 847e87
17 15 5 847e87
16 1 6 847e87
17 1 6 847e87
18 1 6 696a6a
19 1 6 696a6a
16 2 6 847e87
17 2 6 847e87
16 3 6 847e87
17 3 6 847e87
16 4 6 847e87
17 4 6 847e87
16 5 6 847e87
17 5 6 847e87
16 6 6 847e87
17 6 6 847e87
16 7 6 847e87
17 7 6 847e87
16 8 6 847e87
17 8 6 847e87
16 9 6 847e87
17 9 6 847e87
16 10 6 847e87
17 10 6 847e87
16 11 6 847e87
17 11 6 847e87
16 12 6 847e87
17 12 6 847e87
16 13 6 847e87
17 13 6 847e87
16 14 6 847e87
17 14 6 847e87
16 15 6 847e87
17 15 6 847e87
16 1 7 847e87
17 1 7 847e87
16 2 7 847e87
17 2 7 847e87
16 3 7 847e87
17 3 7 847e87
16 4 7 847e87
17 4 7 847e87
16 5 7 847e87
17 5 7 847e87
16 6 7 847e87
17 6 7 847e87
16 7 7 847e87
17 7 7 847e87
16 8 7 847e87
17 8 7 847e87
16 9 7 847e87
17 9 7 847e87
16 10 7 847e87
17 10 7 847e87
16 11 7 847e87
17 11 7 847e87
16 12 7 847e87
17 12 7 847e87
16 13 7 847e87
17 13 7 847e87
16 14 7 847e87
17 14 7 847e87
16 15 7 847e87
17 15 7 847e87
16 1 8 847e87
17 1 8 847e87
18 1 8 696a6a
19 1 8 696a6a
16 2 8 847e87
17 2 8 847e87
16 3 8 847e87
17 3 8 847e87
16 4 8 847e87
17 4 8 847e87
16 5 8 847e87
17 5 8 847e87
16 6 8 847e87
17 6 8 847e87
16 7 8 847e87
17 7 8 847e87
16 8 8 847e87
17 8 8 847e87
16 9 8 847e87
17 9 8 847e87
16 10 8 847e87
17 10 8 847e87
16 11 8 847e87
17 11 8 847e87
16 12 8 847e87
17 12 8 847e87
16 13 8 847e87
17 13 8 847e87
16 14 8 847e87
17 14 8 847e87
16 15 8 847e87
17 15 8 847e87
16 1 9 847e87
17 1 9 847e87
16 2 9 847e87
17 2 9 847e87
16 3 9 847e87
17 3 9 847e87
16 4 9 847e87
17 4 9 847e87
16 5 9 847e87
17 5 9 847e87
16 6 9 847e87
17 6 9 847e87
16 7 9 847e87
17 7 9 847e87
16 8 9 847e87
17 8 9 847e87
16 9 9 847e87
17 9 9 847e87
16 10 9 847e87
17 10 9 847e87
16 11 9 847e87
17 11 9 847e87
16 12 9 847e87
17 12 9 847e87
16 13 9 847e87
17 13 9 847e87
16 14 9 847e87
17 14 9 847e87
16 15 9 847e87
17 15 9 847e87
16 1 10 847e87
17 1 10 847e87
16 2 10 847e87
17 2 10 847e87
16 3 10 847e87
17 3 10 847e87
16 4 10 847e87
17 4 10 847e87
16 5 10 847e87
17 5 10 847e87
16 6 10 847e87
17 6 10 847e87
16 7 10 847e87
17 7 10 847e87
16 8 10 847e87
17 8 10 847e87
16 9 10 847e87
17 9 10 847e87
16 10 10 847e87
17 10 10 847e87
16 11 10 847e87
17 11 10 847e87
16 12 10 847e87
17 12 10 847e87
16 13 10 847e87
17 13 10 847e87
16 14 10 847e87
17 14 10 847e87
16 15 10 847e87
17 15 10 847e87
16 1 11 847e87
17 1 11 847e87
16 2 11 847e87
17 2 11 847e87
16 3 11 847e87
17 3 11 847e87
16 4 11 847e87
17 4 11 847e87
16 5 11 847e87
17 5 11 847e87
16 6 11 847e87
17 6 11 847e87
16 7 11 847e87
17 7 11 847e87
16 8 11 847e87
17 8 11 847e87
16 9 11 847e87
17 9 11 847e87
16 10 11 847e87
17 10 11 847e87
16 11 11 847e87
17 11 11 847e87
16 12 11 847e87
17 12 11 847e87
16 13 11 847e87
17 13 11 847e87
16 14 11 847e87
17 14 11 847e87
16 15 11 847e87
17 15 11 847e87
16 1 12 847e87
17 1 12 847e87
16 2 12 847e87
17 2 12 847e87
16 3 12 847e87
17 3 12 847e87
16 4 12 847e87
17 4 12 847e87
16 5 12 847e87
17 5 12 847e87
16 6 12 847e87
17 6 12 847e87
16 7 12 847e87
17 7 12 847e87
16 8 12 847e87
17 8 12 847e87
16 9 12 847e87
17 9 12 847e87
16 10 12 847e87
17 10 12 847e87
16 11 12 847e87
17 11 12 847e87
16 12 12 847e87
17 12 12 847e87
16 13 12 847e87
17 13 12 847e87
16 14 12 847e87
17 14 12 847e87
16 15 12 847e87
17 15 12 847e87
16 1 13 847e87
17 1 13 847e87
16 2 13 847e87
17 2 13 847e87
16 3 13 847e87
17 3 13 847e87
16 4 13 847e87
17 4 13 847e87
16 5 13 847e87
17 5 13 847e87
16 6 13 847e87
17 6 13 847e87
16 7 13 847e87
17 7 13 847e87
16 8 13 847e87
17 8 13 847e87
16 9 13 847e87
17 9 13 847e87
16 10 13 847e87
17 10 13 847e87
16 11 13 847e87
17 11 13 847e87
16 12 13 847e87
17 12 13 847e87
16 13 13 847e87
17 13 13 847e87
16 14 13 847e87
17 14 13 847e87
16 15 13 847e87
17 15 13 847e87
16 1 14 847e87
17 1 14 847e87
16 2 14 847e87
17 2 14 847e87
16 3 14 847e87
17 3 14 847e87
16 4 14 847e87
17 4 14 847e87
16 5 14 847e87
17 5 14 847e87
16 6 14 847e87
17 6 14 847e87
16 7 14 847e87
17 7 14 847e87
16 8 14 847e87
17 8 14 847e87
16 9 14 847e87
17 9 14 847e87
16 10 14 847e87
17 10 14 847e87
16 11 14 847e87
17 11 14 847e87
16 12 14 847e87
17 12 14 847e87
16 13 14 847e87
17 13 14 847e87
16 14 14 847e87
17 14 14 847e87
16 15 14 847e87
17 15 14 847e87
16 1 15 847e87
17 1 15 847e87
16 2 15 847e87
17 2 15 847e87
16 3 15 847e87
17 3 15 847e87
16 4 15 847e87
17 4 15 847e87
16 5 15 847e87
17 5 15 847e87
16 6 15 847e87
17 6 15 847e87
16 7 15 847e87
17 7 15 847e87
16 8 15 847e87
17 8 15 847e87
16 9 15 847e87
17 9 15 847e87
16 10 15 847e87
17 10 15 847e87
16 11 15 847e87
17 11 15 847e87
16 12 15 847e87
17 12 15 847e87
16 13 15 847e87
17 13 15 847e87
16 14 15 847e87
17 14 15 847e87
16 15 15 847e87
17 15 15 847e87
2 16 0 696a6a
3 16 0 696a6a
4 16 0 696a6a
5 16 0 696a6a
14 16 0 696a6a
15 16 0 696a6a
2 16 1 847e87
3 16 1 847e87
4 16 1 847e87
5 16 1 847e87
14 16 1 847e87
15 16 1 847e87
2 16 2 847e87
3 16 2 847e87
4 16 2 847e87
5 16 2 847e87
6 16 2 9badb7
7 16 2 9badb7
8 16 2 9badb7
9 16 2 9badb7
10 16 2 9badb7
11 16 2 9badb7
12 16 2 9badb7
13 16 2 9badb7
14 16 2 847e87
15 16 2 847e87
2 16 3 847e87
3 16 3 847e87
4 16 3 847e87
5 16 3 847e87
6 16 3 847e87
7 16 3 847e87
8 16 3 847e87
9 16 3 847e87
10 16 3 847e87
11 16 3 847e87
12 16 3 847e87
13 16 3 847e87
14 16 3 847e87
15 16 3 847e87
2 16 4 847e87
3 16 4 847e87
4 16 4 847e87
5 16 4 847e87
6 16 4 847e87
7 16 4 847e87
8 16 4 847e87
9 16 4 847e87
10 16 4 847e87
11 16 4 847e87
12 16 4 847e87
13 16 4 847e87
14 16 4 847e87
15 16 4 847e87
2 16 5 847e87
3 16 5 847e87
4 16 5 847e87
5 16 5 847e87
6 16 5 847e87
7 16 5 847e87
8 16 5 847e87
9 16 5 847e87
10 16 5 847e87
11 16 5 847e87
12 16 5 847e87
13 16 5 847e87
14 16 5 847e87
15 16 5 847e87
2 16 6 847e87
3 16 6 847e87
4 16 6 847e87
5 16 6 847e87
6 16 6 847e87
7 16 6 847e87
8 16 6 847e87
9 16 6 847e87
10 16 6 847e87
11 16 6 847e87
12 16 6 847e87
13 16 6 847e87
14 16 6 847e87
15 16 6 847e87
2 16 7 847e87
3 16 7 847e87
4 16 7 847e87
5 16 7 847e87
6 16 7 847e87
7 16 7 847e87
8 16 7 847e87
9 16 7 847e87
10 16 7 847e87
11 16 7 847e87
12 16 7 847e87
13 16 7 847e87
14 16 7 847e87
15 16 7 847e87
2 16 8 847e87
3 16 8 847e87
4 16 8 847e87
5 16 8 847e87
6 16 8 847e87
7 16 8 847e87
8 16 8 847e87
9 16 8 847e87
10 16 8 847e87
11 16 8 847e87
12 16 8 847e87
13 16 8 847e87
14 16 8 847e87
15 16 8 847e87
2 16 9 847e87
3 16 9 847e87
4 16 9 847e87
5 16 9 847e87
6 16 9 847e87
7 16 9 847e87
8 16 9 847e87
9 16 9 847e87
10 16 9 847e87
11 16 9 847e87
12 16 9 847e87
13 16 9 847e87
14 16 9 847e87
15 16 9 847e87
2 16 10 847e87
3 16 10 847e87
4 16 10 847e87
5 16 10 847e87
6 16 10 847e87
7 16 10 847e87
8 16 10 847e87
9 16 10 847e87
10 16 10 847e87
11 16 10 847e87
12 16 10 847e87
13 16 10 847e87
14 16 10 847e87
15 16 10 847e87
2 16 11 847e87
3 16 11 847e87
4 16 11 847e87
5 16 11 847e87
6 16 11 847e87
7 16 11 847e87
8 16 11 847e87
9 16 11 847e87
10 16 11 847e87
11 16 11 847e87
12 16 11 847e87
13 16 11 847e87
14 16 11 847e87
15 16 11 847e87
2 16 12 847e87
3 16 12 847e87
4 16 12 847e87
5 16 12 847e87
6 16 12 847e87
7 16 12 847e87
8 16 12 847e87
9 16 12 847e87
10 16 12 847e87
11 16 12 847e87
12 16 12 847e87
13 16 12 847e87
14 16 12 847e87
15 16 12 847e87
8 17 12 696a6a
9 17 12 696a6a
10 17 12 696a6a
11 17 12 696a6a
8 18 12 696a6a
9 18 12 696a6a
10 18 12 696a6a
11 18 12 696a6a
8 19 12 696a6a
9 19 12 696a6a
10 19 12 696a6a
11 19 12 696a6a
2 16 13 847e87
3 16 13 847e87
4 16 13 847e87
5 16 13 847e87
6 16 13 847e87
7 16 13 847e87
8 16 13 847e87
9 16 13 847e87
10 16 13 847e87
11 16 13 847e87
12 16 13 847e87
13 16 13 847e87
14 16 13 847e87
15 16 13 847e87
8 17 13 696a6a
9 17 13 696a6a
10 17 13 696a6a
11 17 13 696a6a
8 18 13 696a6a
9 18 13 696a6a
10 18 13 696a6a
11 18 13 696a6a
8 19 13 696a6a
9 19 13 696a6a
10 19 13 696a6a
11 19 13 696a6a
2 16 14 847e87
3 16 14 847e87
4 16 14 847e87
5 16 14 847e87
6 16 14 847e87
7 16 14 847e87
8 16 14 847e87
9 16 14 847e87
10 16 14 847e87
11 16 14 847e87
12 16 14 847e87
13 16 14 847e87
14 16 14 847e87
15 16 14 847e87
8 17 14 696a6a
9 17 14 696a6a
10 17 14 696a6a
11 17 14 696a6a
8 18 14 696a6a
9 18 14 696a6a
10 18 14 696a6a
11 18 14 696a6a
8 19 14 696a6a
9 19 14 696a6a
10 19 14 696a6a
11 19 14 696a6a
2 16 15 847e87
3 16 15 847e87
4 16 15 847e87
5 16 15 847e87
6 16 15 847e87
7 16 15 847e87
8 16 15 847e87
9 16 15 847e87
10 16 15 847e87
11 16 15 847e87
12 16 15 847e87
13 16 15 847e87
14 16 15 847e87
15 16 15 847e87
8 17 15 696a6a
9 17 15 696a6a
10 17 15 696a6a
11 17 15 696a6a
8 18 15 696a6a
9 18 15 696a6a
10 18 15 696a6a
11 18 15 696a6a
8 19 15 696a6a
9 19 15 696a6a
10 19 15 696a6a
11 19 15 696a6a
16 16 0 696a6a
17 16 0 696a6a
16 16 1 847e87
17 16 1 847e87
16 16 2 847e87
17 16 2 847e87
16 16 3 847e87
17 16 3 847e87
16 16 4 847e87
17 16 4 847e87
16 16 5 847e87
17 16 5 847e87
16 16 6 847e87
17 16 6 847e87
16 16 7 847e87
17 16 7 847e87
16 16 8 847e87
17 16 8 847e87
16 16 9 847e87
17 16 9 847e87
16 16 10 847e87
17 16 10 847e87
16 16 11 847e87
17 16 11 847e87
16 16 12 847e87
17 16 12 847e87
16 16 13 847e87
17 16 13 847e87
16 16 14 847e87
17 16 14 847e87
16 16 15 847e87
17 16 15 847e87
2 1 16 847e87
3 1 16 696a6a
4 1 16 696a6a
5 1 16 696a6a
6 1 16 847e87
13 1 16 847e87
14 1 16 696a6a
15 1 16 696a6a
2 2 16 847e87
3 2 16 847e87
4 2 16 847e87
5 2 16 847e87
6 2 16 847e87
13 2 16 847e87
14 2 16 847e87
15 2 16 847e87
2 3 16 847e87
3 3 16 847e87
4 3 16 847e87
5 3 16 847e87
6 3 16 847e87
13 3 16 847e87
14 3 16 847e87
15 3 16 847e87
2 1 17 847e87
3 1 17 696a6a
4 1 17 696a6a
5 1 17 696a6a
6 1 17 847e87
13 1 17 847e87
14 1 17 696a6a
15 1 17 696a6a
2 2 17 847e87
3 2 17 847e87
4 2 17 847e87
5 2 17 847e87
6 2 17 847e87
13 2 17 847e87
14 2 17 847e87
15 2 17 847e87
2 3 17 847e87
3 3 17 847e87
4 3 17 847e87
5 3 17 847e87
6 3 17 847e87
13 3 17 847e87
14 3 17 847e87
15 3 17 847e87
8 9 17 696a6a
9 9 17 696a6a
10 9 17 696a6a
11 9 17 696a6a
8 10 17 696a6a
9 10 17 696a6a
10 10 17 696a6a
11 10 17 696a6a
8 11 17 696a6a
9 11 17 696a6a
10 11 17 696a6a
11 11 17 696a6a
8 12 17 696a6a
9 12 17 696a6a
10 12 17 696a6a
11 12 17 696a6a
8 13 17 696a6a
9 13 17 696a6a
10 13 17 696a6a
11 13 17 696a6a
8 14 17 696a6a
9 14 17 696a6a
10 14 17 696a6a
11 14 17 696a6a
8 15 17 696a6a
9 15 17 696a6a
10 15 17 696a6a
11 15 17 696a6a
2 1 18 847e87
3 1 18 847e87
4 1 18 847e87
5 1 18 847e87
6 1 18 847e87
13 1 18 847e87
14 1 18 847e87
15 1 18 847e87
2 2 18 847e87
3 2 18 847e87
4 2 18 847e87
5 2 18 847e87
6 2 18 847e87
13 2 18 847e87
14 2 18 847e87
15 2 18 847e87
2 3 18 847e87
3 3 18 847e87
4 3 18 847e87
5 3 18 847e87
6 3 18 847e87
13 3 18 847e87
14 3 18 847e87
15 3 18 847e87
8 9 18 696a6a
9 9 18 696a6a
10 9 18 696a6a
11 9 18 696a6a
8 10 18 696a6a
9 10 18 696a6a
10 10 18 696a6a
11 10 18 696a6a
8 11 18 696a6a
9 11 18 696a6a
10 11 18 696a6a
11 11 18 696a6a
8 12 18 696a6a
9 12 18 696a6a
10 12 18 696a6a
11 12 18 696a6a
8 13 18 696a6a
9 13 18 696a6a
10 13 18 696a6a
11 13 18 696a6a
8 14 18 696a6a
9 14 18 696a6a
10 14 18 696a6a
11 14 18 696a6a
8 15 18 696a6a
9 15 18 696a6a
10 15 18 696a6a
11 15 18 696a6a
8 9 19 696a6a
9 9 19 696a6a
10 9 19 696a6a
11 9 19 696a6a
8 10 19 696a6a
9 10 19 696a6a
10 10 19 696a6a
11 10 19 696a6a
8 11 19 696a6a
9 11 19 696a6a
10 11 19 696a6a
11 11 19 696a6a
8 12 19 696a6a
9 12 19 696a6a
10 12 19 696a6a
11 12 19 696a6a
8 13 19 696a6a
9 13 19 696a6a
10 13 19 696a6a
11 13 19 696a6a
8 14 19 696a6a
9 14 19 696a6a
10 14 19 696a6a
11 14 19 696a6a
8 15 19 696a6a
9 15 19 696a6a
10 15 19 696a6a
11 15 19 696a6a
16 1 16 696a6a
17 1 16 847e87
16 2 16 847e87
17 2 16 847e87
16 3 16 847e87
17 3 16 847e87
16 1 17 696a6a
17 1 17 847e87
16 2 17 847e87
17 2 17 847e87
16 3 17 847e87
17 3 17 847e87
16 1 18 847e87
17 1 18 847e87
16 2 18 847e87
17 2 18 847e87
16 3 18 847e87
17 3 18 847e87
8 17 16 696a6a
9 17 16 696a6a
10 17 16 696a6a
11 17 16 696a6a
8 18 16 696a6a
9 18 16 696a6a
10 18 16 696a6a
11 18 16 696a6a
8 19 16 696a6a
9 19 16 696a6a
10 19 16 696a6a
11 19 16 696a6a
8 16 17 696a6a
9 16 17 696a6a
10 16 17 696a6a
11 16 17 696a6a
8 17 17 696a6a
9 17 17 696a6a
10 17 17 696a6a
11 17 17 696a6a
8 18 17 696a6a
9 18 17 696a6a
10 18 17 696a6a
11 18 17 696a6a
8 19 17 696a6a
9 19 17 696a6a
10 19 17 696a6a
11 19 17 696a6a
8 16 18 696a6a
9 16 18 696a6a
10 16 18 696a6a
11 16 18 696a6a
8 17 18 696a6a
9 17 18 696a6a
10 17 18 696a6a
11 17 18 696a6a
8 18 18 696a6a
9 18 18 696a6a
10 18 18 696a6a
11 18 18 696a6a
8 19 18 696a6a
9 19 18 696a6a
10 19 18 696a6a
11 19 18 696a6a
8 16 19 696a6a
9 16 19 696a6a
10 16 19 696a6a
11 16 19 696a6a
8 17 19 696a6a
9 17 19 696a6a
10 17 19 696a6a
11 17 19 696a6a
8 18 19 696a6a
9 18 19 696a6a
10 18 19 696a6a
11 18 19 696a6a
8 19 19 696a6a
9 19 19 696a6a
10 19 19 696a6a
11 19 19 696a6a
